{"name": "test_xfail_unexpected_pass", "status": "passed", "statusDetails": {"message": "XPASS this test is expecting failure"}, "description": "this test is an xfail that will be marked as unexpected success", "attachments": [{"name": "stdout", "source": "9bcd796d-27b0-478d-b0f8-6cf59588a1c8-attachment.txt", "type": "text/plain"}], "start": 1623156792179, "stop": 1623156792180, "uuid": "546cbbf0-d748-4bda-89eb-a6b9062a266f", "historyId": "44c5e46764f73a56326e54cefd8e8e86", "testCaseId": "7f751c4c09f6823767f5ddca0787ab1c", "fullName": "Test_BlogAllure#test_xfail_unexpected_pass", "labels": [{"name": "tag", "value": "@pytest.mark.xfail(condition=<function <lambda> at 0x000001B0BABDE430>, reason='this test is expecting failure')"}, {"name": "suite", "value": "Test_BlogAllure"}, {"name": "host", "value": "MININT-I84MTFS"}, {"name": "thread", "value": "14344-MainThread"}, {"name": "framework", "value": "pytest"}, {"name": "language", "value": "cpython3"}, {"name": "package", "value": "Test_BlogAllure"}]}